[section#except.uncaught
    [:en] The [`std::uncaught_exceptions] function
    [:zh_CN] [`std::uncaught_exceptions] 函数
[:][%@lib uncaught_exceptions]
]

[para]
[:en]
An exception is considered uncaught after completing the initialization of the
exception object ([#except.throw]) until completing the activation of a handler
for the exception ([#except.handle]).
[:zh_CN]
在一个异常对象的初始化完成之后（[#except.throw]）直到该异常的某个处理器完成激活
（[#except.handle]）之前，异常被当作未被捕获。

[begin:note]
[:en]
As a consequence, an exception is considered uncaught during any stack unwinding
resulting from it being thrown.
[:zh_CN]
其后果是，处于由抛出异常而导致的栈解退过程中时，该异常被认为是未被捕获的。
[end:note]

[:en]
If an exception is rethrown ([#expr.throw], [#propagation]), it is considered
uncaught from the point of rethrow until the rethrown exception is caught.
[:zh_CN]
若该异常被重新抛出（[#expr.throw]，[#propagation]），则从重新抛出点直到重新抛出
的异常被捕获之前，异常被当作未被捕获。

[:en]
The function [`std::uncaught_exceptions] ([#uncaught.exceptions]) returns the
number of uncaught exceptions in the current thread.
[:zh_CN]
函数 [`std::uncaught_exceptions]（[#uncaught.exceptions]）返回当前线程中未捕获
异常的个数。
